同时catch多个异常：

```java
class Exception1 extends Exception {}
class Exception2 extends Exception {}
public class App {
    static void f() throws Exception1, Exception2 {}
    public static void main(String[] args) {
        
        try {
            f();
        }
        catch(Exception1 | Exception2 ex) {} // Multi-Catch
    }
}
```

各种重抛异常方式对比：

```java
public class App {
    static void f() throws Exception {
        throw new Exception();
    }
    static void g() throws Exception {
        try {
            throw new Exception();
        } catch(Exception e) {
            System.err.println("Exception caught in g()");
            e.printStackTrace();
            throw e;
        }
    }
    static void h() throws Exception {
        try {
            throw new Exception();
        } catch(Exception e) {
            System.err.println("Exception caught in h()");
            e.printStackTrace();
            throw (Exception)e.fillInStackTrace();
        }
    }
    static void j() throws Exception {
        try {
            throw new Exception();
        } catch(Exception e) {
            System.err.println("Exception caught in j()");
            e.printStackTrace();
            throw new Exception();
        }
    }
    public static void main(String[] args) {
        try {
            g();
        } catch (Exception e) {
            System.err.println("Exception caught in main()");
            e.printStackTrace();
        }
        System.err.println("+++++");
        try {
            h();
        } catch (Exception e) {
            System.err.println("Exception caught in main()");
            e.printStackTrace();
        }
        System.err.println("+++++");try {
            h();
        } catch (Exception e) {
            System.err.println("Exception caught in main()");
            e.printStackTrace();
        }
    }
}
/* Output
Exception caught in g()
java.lang.Exception
        at com.example.zck.five.App.g(App.java:40)   
        at com.example.zck.five.App.main(App.java:67)
Exception caught in main()
java.lang.Exception
        at com.example.zck.five.App.g(App.java:40)   
        at com.example.zck.five.App.main(App.java:67)
+++++
Exception caught in h()
java.lang.Exception
        at com.example.zck.five.App.h(App.java:49)   
        at com.example.zck.five.App.main(App.java:74)
Exception caught in main()
java.lang.Exception
        at com.example.zck.five.App.h(App.java:53)
        at com.example.zck.five.App.main(App.java:74)
+++++
Exception caught in h()
java.lang.Exception
        at com.example.zck.five.App.h(App.java:49)
        at com.example.zck.five.App.main(App.java:80)
Exception caught in main()
java.lang.Exception
        at com.example.zck.five.App.h(App.java:53)
        at com.example.zck.five.App.main(App.java:80)
*/
```

只要控制流出了try block，与之对应的finally块一定会被执行。

避免在finally块中使用return、continue、throw等语句使控制跳出finally块，因为这会掩盖对应try-catch块中抛出的异常。

```java
public static void main(String[] args) {
    try {
        throw new Exception();
    } finally {
        return;
    }
}
/* program ends normally! */
public static void main(String[] args) {
    for(int i = 0; i < 10; ++i) {
        try {
            throw new Exception();
        } finally {
            continue;
        }    
    }
}
/* program ends normally! */
```

```java
class VeryImportanceException extends Exception {}
class UnimportantException extends Exception {}
public class App {
    public static void main(String[] args) throws UnimportantException {
        try {
            throw new VeryImportanceException();
        } finally {
            throw new UnimportantException();
        }
    }
}
/* 
Exception in thread "main" com.example.zck.five.UnimportantException
        at com.example.zck.five.App.main(App.java:40)
*/
```

子类构造函数中无法catch父类构造函数的异常：

```java
class E1 extends Exception {}
class E2 extends Exception {}

class A {
    A() throws E1 {}
}
class B extends A {
    B() throws E2 {
        try {
            super(); // err: Constructor call must be the first statement in a constructor.
        } catch (E1 e1) {}
    }
}
```

尽量使用try-with-resource结构：

```java
class A implements AutoCloseable {
    A() {
        System.err.println("++++++Create A++++++");
    }
    @Override
    public void close() {
        System.err.println("++++++Close A++++++");
    }
    void f() {}
}
class B implements AutoCloseable {
    B() throws Exception {
        System.err.println("++++++Create B++++++");
        throw new Exception();
    }
    @Override
    public void close() {
        System.err.println("++++++Close B++++++");
    }
    void f() {}
}
class C implements AutoCloseable {
    C() {
        System.err.println("++++++Create C++++++");
    }
    @Override
    public void close() {
        System.err.println("++++++Close C++++++");
    }
    void f() throws Exception {throw new Exception();}
}
class D implements AutoCloseable {
    D() throws Exception {
        System.err.println("++++++Create D++++++");
    }
    @Override
    public void close() throws Exception {
        System.err.println("++++++Close D++++++");
        throw new Exception();
    }
    void f() {}
}
public class App {
    public static void main(String[] args) {
        try(
        A a = new A();
        B b = new B();
        C c = new C();
        D d = new D();) {
            a.f();
            b.f();
            c.f();
            d.f();
        } catch(Exception e) {
            System.err.println("++++++Exception caught++++++");
            e.printStackTrace();
        }
    }
}
/* Output
++++++Create A++++++
++++++Create B++++++
++++++Close A++++++
++++++Exception caught++++++
java.lang.Exception
        at com.example.zck.five.B.<init>(App.java:45)
        at com.example.zck.five.App.main(App.java:78)
*/

public class App {
    public static void main(String[] args) {
        try(
        A a = new A();
        C c = new C();
        D d = new D();) {
            a.f();
            c.f();
            d.f();
        } catch(Exception e) {
            System.err.println("++++++Exception caught++++++");
            e.printStackTrace();
        }
    }
}
/* Output
++++++Create A++++++
++++++Create C++++++
++++++Create D++++++
++++++Close D++++++
++++++Close C++++++
++++++Close A++++++
++++++Exception caught++++++
java.lang.Exception
        at com.example.zck.five.C.f(App.java:61)
        at com.example.zck.five.App.main(App.java:81)
        Suppressed: java.lang.Exception
                at com.example.zck.five.D.close(App.java:70)
                at com.example.zck.five.App.main(App.java:83)
*/

public class App {
    public static void main(String[] args) {
        try(
        A a = new A();
        D d = new D();) {
            a.f();
            d.f();
        } catch(Exception e) {
            System.err.println("++++++Exception caught++++++");
            e.printStackTrace();
        }
    }
}
/* Output:
++++++Create A++++++
++++++Create D++++++
++++++Close D++++++
++++++Close A++++++
++++++Exception caught++++++
java.lang.Exception
        at com.example.zck.five.D.close(App.java:70)
        at com.example.zck.five.App.main(App.java:81)
*/
```

如果在catch块中不知道该如何处理一个checked异常，可以把它转成一个unchecked异常再抛出。

```java
void f() {
    try{
        throw new SimpleException();
    } catch(SimpleException e) {
        throw new RuntimeException(e);
    }
}
```

不要随意catch自己不知道该如何处理的异常。
